Workbook

Sheet Report
A1: Report shows all builds for which failures classification is possible
A2: Organization filter: MGU22%
A3: Baseline filter: MGU22
A4: Date from: 03-08-2026
A5: Date to: 10-08-2026
A6: Generated at: 10.08.2026 06:41:24
A8: EXECUTION_ID | B8: ORGANIZATION | C8: CI_STAGE | D8: JOB | E8: RESULT | F8: URL | G8: CI_GATE_URL | H8: TIMESTAMP | I8: CATEGORY | J8: SUB-CATEGORY | K8: COMMENT | L8: TICKET | M8: CLASSIFIED_AT | N8: CLASSIFIED_BY
A9: 155030349 | B9: MGU22 - SYSTEM INTEGRATION | C9: SINT | D9: SINT---MGU22_SWINT_04---PLATFORM_SW_BUILD/BITBAKE_TARGETS=mgu22 | E9: UNSTABLE | F9: https://asc.bmwgroup.net/bci/00780/job/SINT---MGU22_SWINT_04---PLATFORM_SW_BUILD/BITBAKE_TARGETS=mgu22/1594 | G9: https://asc.bmwgroup.net/bci/00780/job/SINT---MGU22_SWINT_04/1749 | H9: 46237.466 | I9: REGULAR_BUILD_FAILURE | J9: BUILD_BITBAKE_FAILURE | K9: Automatically classified by BCI | M9: 46237.618 | N9: SYSTEM
A10: 155030355 | B10: MGU22 - SYSTEM INTEGRATION | C10: SINT | D10: SINT---MGU22_SWINT_01---PLATFORM_SW_BUILD/BITBAKE_TARGETS=mgu22 | E10: ABORTED | F10: https://asc.bmwgroup.net/bci/00780/job/SINT---MGU22_SWINT_01---PLATFORM_SW_BUILD/BITBAKE_TARGETS=mgu22/3716 | G10: https://asc.bmwgroup.net/bci/00780/job/SINT---MGU22_SWINT_01/4191 | H10: 46237.466 | I10: REGULAR_BUILD_FAILURE | J10: BUILD_USER_ABORT_FAILURE | K10: Automatically classified by BCI | M10: 46237.62 | N10: SYSTEM
A11: 155031157 | B11: MGU22 - BASE SYSTEM | C11: SINT | D11: SINT---MGU22_BSYS_02---PLATFORM_SYSTEM_TESTS_HARDWARE_B1_HIGHF_22 | E11: UNSTABLE | F11: https://asc.bmwgroup.net/bci/08480/job/SINT---MGU22_BSYS_02---PLATFORM_SYSTEM_TESTS_HARDWARE_B1_HIGHF_22/1126 | G11: https://asc.bmwgroup.net/bci/08480/job/SINT---MGU22_BSYS_02/1830 | H11: 46237.6 | I11: IRREGULAR_TEST_FAILURE | J11: TEST_OTHER_IRREGULAR_FAILURE | K11: MGU22: Test-execution-environment.posttests_can_asc_sanity_tests case failing | L11: SIT-53324 | M11: 46238.291 | N11: qxz5hes
A12: 155031332 | B12: MGU22 - SYSTEM INTEGRATION | C12: SINT | D12: SINT---MGU22_SWINT_04---PLATFORM_SW_BUILD/BITBAKE_TARGETS=mgu22 | E12: UNSTABLE | F12: https://asc.bmwgroup.net/bci/00780/job/SINT---MGU22_SWINT_04---PLATFORM_SW_BUILD/BITBAKE_TARGETS=mgu22/1595 | G12: https://asc.bmwgroup.net/bci/00780/job/SINT---MGU22_SWINT_04/1750 | H12: 46237.621 | I12: REGULAR_BUILD_FAILURE | J12: BUILD_BITBAKE_FAILURE | K12: Automatically classified by BCI | M12: 46237.733 | N12: SYSTEM
A13: 155031367 | B13: MGU22 - SYSTEM INTEGRATION | C13: SINT | D13: SINT---MGU22_SWINT_01---PLATFORM_SW_BUILD/BITBAKE_TARGETS=mgu22 | E13: UNSTABLE | F13: https://asc.bmwgroup.net/bci/00780/job/SINT---MGU22_SWINT_01---PLATFORM_SW_BUILD/BITBAKE_TARGETS=mgu22/3717 | G13: https://asc.bmwgroup.net/bci/00780/job/SINT---MGU22_SWINT_01/4192 | H13: 46237.621 | I13: REGULAR_BUILD_FAILURE | J13: BUILD_BITBAKE_FAILURE | K13: Automatically classified by BCI | M13: 46237.712 | N13: SYSTEM
A14: 155049102 | B14: MGU22 - SYSTEM INTEGRATION | C14: SINT | D14: SINT---MGU22_DEVCI_01---PLATFORM_SYSTEM_TESTS_HARDWARE_B1_HIGHF_22 | E14: UNSTABLE | F14: https://asc.bmwgroup.net/bci/03480/job/SINT---MGU22_DEVCI_01---PLATFORM_SYSTEM_TESTS_HARDWARE_B1_HIGHF_22/5300 | G14: https://asc.bmwgroup.net/bci/03480/job/SINT---MGU22_DEVCI_01/9270 | H14: 46238.224 | M14: 46238.331 | N14: SYSTEM
A15: 155058873 | B15: MGU22 - SYSTEM INTEGRATION | C15: SINT | D15: SINT---MGU22_DEVCI01_01_TBS---PLATFORM_SYSTEM_TESTS_VIRTUAL_MGU22 | E15: UNSTABLE | F15: https://asc.bmwgroup.net/bci/07080/job/SINT---MGU22_DEVCI01_01_TBS---PLATFORM_SYSTEM_TESTS_VIRTUAL_MGU22/972 | G15: https://asc.bmwgroup.net/bci/07080/job/SINT---MGU22_DEVCI01_01_TBS/1191 | H15: 46238.595 | I15: IRREGULAR_TEST_FAILURE | J15: TEST_OTHER_IRREGULAR_FAILURE | K15: MGU22: Test-execution-environment.posttests_can_asc_sanity_tests case failing | L15: SIT-53324 | M15: 46239.302 | N15: qxz5hes
A16: 155070050 | B16: MGU22 - SYSTEM INTEGRATION | C16: SINT | D16: SINT---MGU22_DEVCI01_01_TBS---PLATFORM_SYSTEM_TESTS_HARDWARE_B1_HIGHF_22_5 | E16: UNSTABLE | F16: https://asc.bmwgroup.net/bci/07080/job/SINT---MGU22_DEVCI01_01_TBS---PLATFORM_SYSTEM_TESTS_HARDWARE_B1_HIGHF_22_5/916 | G16: https://asc.bmwgroup.net/bci/07080/job/SINT---MGU22_DEVCI01_01_TBS/1191 | H16: 46239.143 | I16: IRREGULAR_TEST_FAILURE | J16: TEST_OTHER_IRREGULAR_FAILURE | K16: Setup/Worker issue | M16: 46239.324 | N16: qxz5hes
A17: 155069224 | B17: MGU22 - SYSTEM INTEGRATION | C17: SINT | D17: SINT---MGU22_DEVCI01_01_TBS---PLATFORM_SYSTEM_TESTS_HARDWARE_B1_HIGHF_22_4 | E17: UNSTABLE | F17: https://asc.bmwgroup.net/bci/07080/job/SINT---MGU22_DEVCI01_01_TBS---PLATFORM_SYSTEM_TESTS_HARDWARE_B1_HIGHF_22_4/945 | G17: https://asc.bmwgroup.net/bci/07080/job/SINT---MGU22_DEVCI01_01_TBS/1191 | H17: 46239.033 | M17: 46239.143 | N17: SYSTEM
A18: 155058874 | B18: MGU22 - SYSTEM INTEGRATION | C18: SINT | D18: SINT---MGU22_DEVCI01_01_TBS---PLATFORM_SYSTEM_TESTS_HARDWARE_B1_HIGHF_22 | E18: UNSTABLE | F18: https://asc.bmwgroup.net/bci/07080/job/SINT---MGU22_DEVCI01_01_TBS---PLATFORM_SYSTEM_TESTS_HARDWARE_B1_HIGHF_22/1012 | G18: https://asc.bmwgroup.net/bci/07080/job/SINT---MGU22_DEVCI01_01_TBS/1191 | H18: 46238.595 | M18: 46238.702 | N18: SYSTEM
A19: 155070592 | B19: MGU22 - SYSTEM INTEGRATION | C19: SINT | D19: SINT---MGU22_DEVCI_01---PLATFORM_SYSTEM_TESTS_HARDWARE_B1_HIGHF_22 | E19: UNSTABLE | F19: https://asc.bmwgroup.net/bci/03480/job/SINT---MGU22_DEVCI_01---PLATFORM_SYSTEM_TESTS_HARDWARE_B1_HIGHF_22/5302 | G19: https://asc.bmwgroup.net/bci/03480/job/SINT---MGU22_DEVCI_01/9272 | H19: 46239.225 | I19: IRREGULAR_TEST_FAILURE | J19: TEST_OTHER_IRREGULAR_FAILURE | K19: Setup/Worker issue | M19: 46239.324 | N19: qxz5hes
A20: 155093526 | B20: MGU22 - SYSTEM INTEGRATION | C20: SINT | D20: SINT---MGU22_DEVCI_01---PLATFORM_SYSTEM_TESTS_HARDWARE_B1_HIGHF_22 | E20: UNSTABLE | F20: https://asc.bmwgroup.net/bci/03480/job/SINT---MGU22_DEVCI_01---PLATFORM_SYSTEM_TESTS_HARDWARE_B1_HIGHF_22/5303 | G20: https://asc.bmwgroup.net/bci/03480/job/SINT---MGU22_DEVCI_01/9273 | H20: 46239.825 | I20: IRREGULAR_TEST_FAILURE | J20: TEST_OTHER_IRREGULAR_FAILURE | K20: Setup/Worker issue | M20: 46240.271 | N20: qxz5hes
A21: 155090612 | B21: MGU22 - SYSTEM INTEGRATION | C21: SINT | D21: SINT---MGU22_SWINT_04---PLATFORM_SW_BUILD/BITBAKE_TARGETS=mgu22 | E21: ABORTED | F21: https://asc.bmwgroup.net/bci/00780/job/SINT---MGU22_SWINT_04---PLATFORM_SW_BUILD/BITBAKE_TARGETS=mgu22/1596 | G21: https://asc.bmwgroup.net/bci/00780/job/SINT---MGU22_SWINT_04/1751 | H21: 46239.717 | I21: REGULAR_BUILD_FAILURE | J21: BUILD_USER_ABORT_FAILURE | K21: Automatically classified by BCI | M21: 46239.763 | N21: SYSTEM
A22: 155090617 | B22: MGU22 - SYSTEM INTEGRATION | C22: SINT | D22: SINT---MGU22_SWINT_01---PLATFORM_SW_BUILD/BITBAKE_TARGETS=mgu22 | E22: ABORTED | F22: https://asc.bmwgroup.net/bci/00780/job/SINT---MGU22_SWINT_01---PLATFORM_SW_BUILD/BITBAKE_TARGETS=mgu22/3718 | G22: https://asc.bmwgroup.net/bci/00780/job/SINT---MGU22_SWINT_01/4193 | H22: 46239.717 | I22: REGULAR_BUILD_FAILURE | J22: BUILD_USER_ABORT_FAILURE | K22: Automatically classified by BCI | M22: 46239.763 | N22: SYSTEM
A23: 155097750 | B23: MGU22 - SYSTEM INTEGRATION | C23: SINT | D23: SINT---MGU22_SWINT_01---PLATFORM_SYSTEM_TESTS_HARDWARE_B1_HIGHF_22 | E23: ABORTED | F23: https://asc.bmwgroup.net/bci/00780/job/SINT---MGU22_SWINT_01---PLATFORM_SYSTEM_TESTS_HARDWARE_B1_HIGHF_22/2623 | G23: https://asc.bmwgroup.net/bci/00780/job/SINT---MGU22_SWINT_01/4194 | H23: 46240.064 | I23: REGULAR_BUILD_FAILURE | J23: BUILD_USER_ABORT_FAILURE | K23: Automatically classified by BCI | M23: 46240.231 | N23: SYSTEM
A24: 155097955 | B24: MGU22 - SYSTEM INTEGRATION | C24: SINT | D24: SINT---MGU22_SWINT_04---PLATFORM_SYSTEM_TESTS_HARDWARE_B1_HIGHF_22 | E24: UNSTABLE | F24: https://asc.bmwgroup.net/bci/00780/job/SINT---MGU22_SWINT_04---PLATFORM_SYSTEM_TESTS_HARDWARE_B1_HIGHF_22/960 | G24: https://asc.bmwgroup.net/bci/00780/job/SINT---MGU22_SWINT_04/1752 | H24: 46240.112 | I24: IRREGULAR_TEST_FAILURE | J24: TEST_OTHER_IRREGULAR_FAILURE | K24: MGU22: Test-execution-environment.posttests_can_asc_sanity_tests case failing | L24: SIT-53324 | M24: 46240.271 | N24: qxz5hes
A25: 155108634 | B25: MGU22 - OSIS EU | C25: SINT | D25: SINT---MGU22_OSISEU_01---PLATFORM_SYSTEM_TESTS_HARDWARE_B1_HIGHF_22 | E25: UNSTABLE | F25: https://asc.bmwgroup.net/bci/01480/job/SINT---MGU22_OSISEU_01---PLATFORM_SYSTEM_TESTS_HARDWARE_B1_HIGHF_22/2553 | G25: https://asc.bmwgroup.net/bci/01480/job/SINT---MGU22_OSISEU_01/3587 | H25: 46240.678 | M25: 46240.79 | N25: SYSTEM
A26: 155107551 | B26: MGU22 - SYSTEM INTEGRATION | C26: SINT | D26: SINT---MGU22_DEVCI_02---PLATFORM_SYSTEM_TESTS_HARDWARE_B1_HIGHF_22 | E26: UNSTABLE | F26: https://asc.bmwgroup.net/bci/03480/job/SINT---MGU22_DEVCI_02---PLATFORM_SYSTEM_TESTS_HARDWARE_B1_HIGHF_22/3801 | G26: https://asc.bmwgroup.net/bci/03480/job/SINT---MGU22_DEVCI_02/6349 | H26: 46240.627 | I26: IRREGULAR_TEST_FAILURE | J26: TEST_OTHER_IRREGULAR_FAILURE | K26: MGU22: Test-execution-environment.posttests_can_asc_sanity_tests case failing | L26: SIT-53324 | M26: 46241.32 | N26: qxz5hes
A27: 155111068 | B27: MGU22 - SYSTEM INTEGRATION | C27: SINT | D27: SINT---MGU22_DEVCI01_01_TBS---PLATFORM_SYSTEM_TESTS_HARDWARE_B1_HIGHF_22_2 | E27: UNSTABLE | F27: https://asc.bmwgroup.net/bci/07080/job/SINT---MGU22_DEVCI01_01_TBS---PLATFORM_SYSTEM_TESTS_HARDWARE_B1_HIGHF_22_2/972 | G27: https://asc.bmwgroup.net/bci/07080/job/SINT---MGU22_DEVCI01_01_TBS/1192 | H27: 46240.807 | I27: IRREGULAR_TEST_FAILURE | J27: TEST_OTHER_IRREGULAR_FAILURE | K27: Setup/Worker issue | M27: 46241.319 | N27: qxz5hes
A28: 155107595 | B28: MGU22 - SYSTEM INTEGRATION | C28: SINT | D28: SINT---MGU22_DEVCI01_01_TBS---PLATFORM_SYSTEM_TESTS_HARDWARE_B1_HIGHF_22 | E28: UNSTABLE | F28: https://asc.bmwgroup.net/bci/07080/job/SINT---MGU22_DEVCI01_01_TBS---PLATFORM_SYSTEM_TESTS_HARDWARE_B1_HIGHF_22/1013 | G28: https://asc.bmwgroup.net/bci/07080/job/SINT---MGU22_DEVCI01_01_TBS/1192 | H28: 46240.631 | I28: IRREGULAR_TEST_FAILURE | J28: TEST_OTHER_IRREGULAR_FAILURE | K28: MGU22: Test-execution-environment.posttests_can_asc_sanity_tests case failing | L28: SIT-53324 | M28: 46241.32 | N28: qxz5hes
A29: 155113948 | B29: MGU22 - SYSTEM INTEGRATION | C29: SINT | D29: SINT---MGU22_DEVCI_01---PLATFORM_SYSTEM_TESTS_HARDWARE_B1_HIGHF_22 | E29: UNSTABLE | F29: https://asc.bmwgroup.net/bci/03480/job/SINT---MGU22_DEVCI_01---PLATFORM_SYSTEM_TESTS_HARDWARE_B1_HIGHF_22/5305 | G29: https://asc.bmwgroup.net/bci/03480/job/SINT---MGU22_DEVCI_01/9275 | H29: 46241.227 | I29: IRREGULAR_TEST_FAILURE | J29: TEST_OTHER_IRREGULAR_FAILURE | K29: MGU22: Test-execution-environment.posttests_can_asc_sanity_tests case failing | L29: SIT-53324 | M29: 46241.469 | N29: qxz5hes
A30: 155114212 | B30: MGU22 - SYSTEM INTEGRATION | C30: SINT | D30: SINT---MGU22_SWINT_04---PLATFORM_SYSTEM_TESTS_HARDWARE_B1_HIGHF_22 | E30: UNSTABLE | F30: https://asc.bmwgroup.net/bci/00780/job/SINT---MGU22_SWINT_04---PLATFORM_SYSTEM_TESTS_HARDWARE_B1_HIGHF_22/962 | G30: https://asc.bmwgroup.net/bci/00780/job/SINT---MGU22_SWINT_04/1754 | H30: 46241.293 | I30: IRREGULAR_TEST_FAILURE | J30: TEST_OTHER_IRREGULAR_FAILURE | K30: MGU22: Test-execution-environment.posttests_can_asc_sanity_tests case failing | L30: SIT-53324 | M30: 46241.469 | N30: qxz5hes
A31: 155129972 | B31: MGU22 - SYSTEM INTEGRATION | C31: SINT | D31: SINT---MGU22_SWINT_04---PLATFORM_SW_BUILD/BITBAKE_TARGETS=mgu22 | E31: ABORTED | F31: https://asc.bmwgroup.net/bci/00780/job/SINT---MGU22_SWINT_04---PLATFORM_SW_BUILD/BITBAKE_TARGETS=mgu22/1600 | G31: https://asc.bmwgroup.net/bci/00780/job/SINT---MGU22_SWINT_04/1755 | H31: 46241.447 | I31: REGULAR_BUILD_FAILURE | J31: BUILD_USER_ABORT_FAILURE | K31: Automatically classified by BCI | M31: 46241.448 | N31: SYSTEM
A32: 155130224 | B32: MGU22 - SYSTEM INTEGRATION | C32: SINT | D32: SINT---MGU22_SWINT_04---PLATFORM_SW_BUILD/BITBAKE_TARGETS=mgu22 | E32: UNSTABLE | F32: https://asc.bmwgroup.net/bci/00780/job/SINT---MGU22_SWINT_04---PLATFORM_SW_BUILD/BITBAKE_TARGETS=mgu22/1601 | G32: https://asc.bmwgroup.net/bci/00780/job/SINT---MGU22_SWINT_04/1756 | H32: 46241.452 | I32: REGULAR_BUILD_FAILURE | J32: BUILD_BITBAKE_FAILURE | M32: 46244.276 | N32: qxz5hes
A33: 155155018 | B33: MGU22 - OSIS EU | C33: SINT | D33: SINT---MGU22_OSISEU_01---PLATFORM_SW_BUILD/BITBAKE_TARGETS=mgu22 | E33: UNSTABLE | F33: https://asc.bmwgroup.net/bci/01480/job/SINT---MGU22_OSISEU_01---PLATFORM_SW_BUILD/BITBAKE_TARGETS=mgu22/3206 | G33: https://asc.bmwgroup.net/bci/01480/job/SINT---MGU22_OSISEU_01/3588 | H33: 46241.695 | I33: REGULAR_BUILD_FAILURE | J33: BUILD_BITBAKE_FAILURE | K33: Automatically classified by BCI | M33: 46241.711 | N33: SYSTEM

Sheet Report CI gates
A1: Report shows all CI Gate builds builds for which failures classification is possible
A2: Organization filter: MGU22%
A3: Baseline filter: MGU22
A4: Date from: 03-08-2026
A5: Date to: 10-08-2026
A6: Generated at: 10.08.2026 06:41:24
A8: EXECUTION_ID | B8: ORGANIZATION | C8: CI_STAGE | D8: JOB | E8: RESULT | F8: URL | G8: CI_GATE_URL | H8: TIMESTAMP | I8: HAS_FAILED_SUBCHECKS | J8: CATEGORY | K8: SUB-CATEGORY | L8: COMMENT | M8: TICKET | N8: CLASSIFIED_AT | O8: CLASSIFIED_BY
A9: 155030325 | B9: MGU22 - SYSTEM INTEGRATION | C9: SINT | D9: SINT---MGU22_SWINT_04 | E9: FAILED | F9: https://asc.bmwgroup.net/bci/00780/job/SINT---MGU22_SWINT_04/1749 | H9: 46237.465 | I9: 1 | J9: REGULAR_BUILD_FAILURE | K9: BUILD_BITBAKE_FAILURE | N9: 46237.618 | O9: SYSTEM
A10: 155030327 | B10: MGU22 - SYSTEM INTEGRATION | C10: SINT | D10: SINT---MGU22_SWINT_01 | E10: ABORTED | F10: https://asc.bmwgroup.net/bci/00780/job/SINT---MGU22_SWINT_01/4191 | H10: 46237.465 | I10: 1 | J10: REGULAR_BUILD_FAILURE | K10: BUILD_USER_ABORT_FAILURE | N10: 46237.62 | O10: SYSTEM
A11: 155030940 | B11: MGU22 - BASE SYSTEM | C11: SINT | D11: SINT---MGU22_BSYS_02 | E11: FAILED | F11: https://asc.bmwgroup.net/bci/08480/job/SINT---MGU22_BSYS_02/1830 | H11: 46237.531 | I11: 1 | J11: IRREGULAR_TEST_FAILURE | K11: TEST_OTHER_IRREGULAR_FAILURE | N11: 46237.71 | O11: SYSTEM
A12: 155031291 | B12: MGU22 - SYSTEM INTEGRATION | C12: SINT | D12: SINT---MGU22_SWINT_04 | E12: FAILED | F12: https://asc.bmwgroup.net/bci/00780/job/SINT---MGU22_SWINT_04/1750 | H12: 46237.62 | I12: 1 | J12: REGULAR_BUILD_FAILURE | K12: BUILD_BITBAKE_FAILURE | N12: 46237.733 | O12: SYSTEM
A13: 155031300 | B13: MGU22 - SYSTEM INTEGRATION | C13: SINT | D13: SINT---MGU22_SWINT_01 | E13: FAILED | F13: https://asc.bmwgroup.net/bci/00780/job/SINT---MGU22_SWINT_01/4192 | H13: 46237.62 | I13: 1 | J13: REGULAR_BUILD_FAILURE | K13: BUILD_BITBAKE_FAILURE | N13: 46237.713 | O13: SYSTEM
A14: 155043299 | B14: MGU22 - SYSTEM INTEGRATION | C14: SINT | D14: SINT---MGU22_DEVCI_01 | E14: FAILED | F14: https://asc.bmwgroup.net/bci/03480/job/SINT---MGU22_DEVCI_01/9270 | H14: 46237.919 | I14: 1 | J14: null | K14: null | N14: 46238.332 | O14: SYSTEM
A15: 155055293 | B15: MGU22 - SYSTEM INTEGRATION | C15: SINT | D15: SINT---MGU22_DEVCI01_01_TBS | E15: SUCCESS | F15: https://asc.bmwgroup.net/bci/07080/job/SINT---MGU22_DEVCI01_01_TBS/1191 | H15: 46238.523 | I15: 1 | J15: null || IRREGULAR_TEST_FAILURE | K15: null || TEST_OTHER_IRREGULAR_FAILURE
A16: 155067831 | B16: MGU22 - SYSTEM INTEGRATION | C16: SINT | D16: SINT---MGU22_DEVCI_01 | E16: FAILED | F16: https://asc.bmwgroup.net/bci/03480/job/SINT---MGU22_DEVCI_01/9272 | H16: 46238.92 | I16: 1 | J16: IRREGULAR_TEST_FAILURE | K16: TEST_OTHER_IRREGULAR_FAILURE | N16: 46239.286 | O16: SYSTEM
A17: 155077880 | B17: MGU22 - SYSTEM INTEGRATION | C17: SINT | D17: SINT---MGU22_DEVCI_01 | E17: FAILED | F17: https://asc.bmwgroup.net/bci/03480/job/SINT---MGU22_DEVCI_01/9273 | H17: 46239.522 | I17: 1 | J17: IRREGULAR_TEST_FAILURE | K17: TEST_OTHER_IRREGULAR_FAILURE | N17: 46239.935 | O17: SYSTEM
A18: 155090589 | B18: MGU22 - SYSTEM INTEGRATION | C18: SINT | D18: SINT---MGU22_SWINT_04 | E18: ABORTED | F18: https://asc.bmwgroup.net/bci/00780/job/SINT---MGU22_SWINT_04/1751 | H18: 46239.716 | I18: 1 | J18: REGULAR_BUILD_FAILURE | K18: BUILD_USER_ABORT_FAILURE | N18: 46239.763 | O18: SYSTEM
A19: 155090595 | B19: MGU22 - SYSTEM INTEGRATION | C19: SINT | D19: SINT---MGU22_SWINT_01 | E19: ABORTED | F19: https://asc.bmwgroup.net/bci/00780/job/SINT---MGU22_SWINT_01/4193 | H19: 46239.716 | I19: 1 | J19: REGULAR_BUILD_FAILURE | K19: BUILD_USER_ABORT_FAILURE | N19: 46239.763 | O19: SYSTEM
A20: 155092435 | B20: MGU22 - SYSTEM INTEGRATION | C20: SINT | D20: SINT---MGU22_SWINT_01 | E20: ABORTED | F20: https://asc.bmwgroup.net/bci/00780/job/SINT---MGU22_SWINT_01/4194 | H20: 46239.763 | I20: 1 | J20: REGULAR_BUILD_FAILURE | K20: BUILD_USER_ABORT_FAILURE | N20: 46240.232 | O20: SYSTEM
A21: 155092438 | B21: MGU22 - SYSTEM INTEGRATION | C21: SINT | D21: SINT---MGU22_SWINT_04 | E21: FAILED | F21: https://asc.bmwgroup.net/bci/00780/job/SINT---MGU22_SWINT_04/1752 | H21: 46239.763 | I21: 1 | J21: IRREGULAR_TEST_FAILURE | K21: TEST_OTHER_IRREGULAR_FAILURE | N21: 46240.337 | O21: SYSTEM
A22: 155100753 | B22: MGU22 - OSIS EU | C22: SINT | D22: SINT---MGU22_OSISEU_01 | E22: FAILED | F22: https://asc.bmwgroup.net/bci/01480/job/SINT---MGU22_OSISEU_01/3587 | H22: 46240.458 | I22: 1 | J22: null | K22: null | N22: 46240.79 | O22: SYSTEM
A23: 155105514 | B23: MGU22 - SYSTEM INTEGRATION | C23: SINT | D23: SINT---MGU22_DEVCI_02 | E23: FAILED | F23: https://asc.bmwgroup.net/bci/03480/job/SINT---MGU22_DEVCI_02/6349 | H23: 46240.555 | I23: 1 | J23: IRREGULAR_TEST_FAILURE | K23: TEST_OTHER_IRREGULAR_FAILURE | N23: 46240.735 | O23: SYSTEM
A24: 155105681 | B24: MGU22 - SYSTEM INTEGRATION | C24: SINT | D24: SINT---MGU22_DEVCI01_01_TBS | E24: SUCCESS | F24: https://asc.bmwgroup.net/bci/07080/job/SINT---MGU22_DEVCI01_01_TBS/1192 | H24: 46240.559 | I24: 1 | J24: IRREGULAR_TEST_FAILURE | K24: TEST_OTHER_IRREGULAR_FAILURE
A25: 155111895 | B25: MGU22 - SYSTEM INTEGRATION | C25: SINT | D25: SINT---MGU22_DEVCI_01 | E25: FAILED | F25: https://asc.bmwgroup.net/bci/03480/job/SINT---MGU22_DEVCI_01/9275 | H25: 46240.92 | I25: 1 | J25: IRREGULAR_TEST_FAILURE | K25: TEST_OTHER_IRREGULAR_FAILURE | N25: 46241.335 | O25: SYSTEM
A26: 155112196 | B26: MGU22 - SYSTEM INTEGRATION | C26: SINT | D26: SINT---MGU22_SWINT_04 | E26: FAILED | F26: https://asc.bmwgroup.net/bci/00780/job/SINT---MGU22_SWINT_04/1754 | H26: 46240.944 | I26: 1 | J26: IRREGULAR_TEST_FAILURE | K26: TEST_OTHER_IRREGULAR_FAILURE | N26: 46241.407 | O26: SYSTEM
A27: 155129916 | B27: MGU22 - SYSTEM INTEGRATION | C27: SINT | D27: SINT---MGU22_SWINT_04 | E27: ABORTED | F27: https://asc.bmwgroup.net/bci/00780/job/SINT---MGU22_SWINT_04/1755 | H27: 46241.446 | I27: 1 | J27: REGULAR_BUILD_FAILURE | K27: BUILD_USER_ABORT_FAILURE | N27: 46241.448 | O27: SYSTEM
A28: 155130118 | B28: MGU22 - SYSTEM INTEGRATION | C28: SINT | D28: SINT---MGU22_SWINT_04 | E28: FAILED | F28: https://asc.bmwgroup.net/bci/00780/job/SINT---MGU22_SWINT_04/1756 | H28: 46241.451 | I28: 1 | J28: REGULAR_BUILD_FAILURE | K28: BUILD_BITBAKE_FAILURE | N28: 46241.682 | O28: SYSTEM
A29: 155154961 | B29: MGU22 - OSIS EU | C29: SINT | D29: SINT---MGU22_OSISEU_01 | E29: FAILED | F29: https://asc.bmwgroup.net/bci/01480/job/SINT---MGU22_OSISEU_01/3588 | H29: 46241.694 | I29: 1 | J29: REGULAR_BUILD_FAILURE | K29: BUILD_BITBAKE_FAILURE | N29: 46241.711 | O29: SYSTEM

Sheet Report Subchecks
A1: Report shows all Subcheck builds for which failures classification is possible
A2: Organization filter: MGU22%
A3: Baseline filter: MGU22
A4: Date from: 03-08-2026
A5: Date to: 10-08-2026
A6: Generated at: 10.08.2026 06:41:24
A8: EXECUTION_ID | B8: ORGANIZATION | C8: CI_STAGE | D8: JOB | E8: RESULT | F8: URL | G8: CI_GATE_URL | H8: TIMESTAMP | I8: CATEGORY | J8: SUB-CATEGORY | K8: COMMENT | L8: TICKET | M8: CLASSIFIED_AT | N8: CLASSIFIED_BY
A9: 155030349 | B9: MGU22 - SYSTEM INTEGRATION | C9: SINT | D9: SINT---MGU22_SWINT_04---PLATFORM_SW_BUILD/BITBAKE_TARGETS=mgu22 | E9: UNSTABLE | F9: https://asc.bmwgroup.net/bci/00780/job/SINT---MGU22_SWINT_04---PLATFORM_SW_BUILD/BITBAKE_TARGETS=mgu22/1594 | G9: https://asc.bmwgroup.net/bci/00780/job/SINT---MGU22_SWINT_04/1749 | H9: 46237.466 | I9: REGULAR_BUILD_FAILURE | J9: BUILD_BITBAKE_FAILURE | K9: Automatically classified by BCI | M9: 46237.618 | N9: SYSTEM
A10: 155030355 | B10: MGU22 - SYSTEM INTEGRATION | C10: SINT | D10: SINT---MGU22_SWINT_01---PLATFORM_SW_BUILD/BITBAKE_TARGETS=mgu22 | E10: ABORTED | F10: https://asc.bmwgroup.net/bci/00780/job/SINT---MGU22_SWINT_01---PLATFORM_SW_BUILD/BITBAKE_TARGETS=mgu22/3716 | G10: https://asc.bmwgroup.net/bci/00780/job/SINT---MGU22_SWINT_01/4191 | H10: 46237.466 | I10: REGULAR_BUILD_FAILURE | J10: BUILD_USER_ABORT_FAILURE | K10: Automatically classified by BCI | M10: 46237.62 | N10: SYSTEM
A11: 155031157 | B11: MGU22 - BASE SYSTEM | C11: SINT | D11: SINT---MGU22_BSYS_02---PLATFORM_SYSTEM_TESTS_HARDWARE_B1_HIGHF_22 | E11: UNSTABLE | F11: https://asc.bmwgroup.net/bci/08480/job/SINT---MGU22_BSYS_02---PLATFORM_SYSTEM_TESTS_HARDWARE_B1_HIGHF_22/1126 | G11: https://asc.bmwgroup.net/bci/08480/job/SINT---MGU22_BSYS_02/1830 | H11: 46237.6 | I11: IRREGULAR_TEST_FAILURE | J11: TEST_OTHER_IRREGULAR_FAILURE | K11: MGU22: Test-execution-environment.posttests_can_asc_sanity_tests case failing | L11: SIT-53324 | M11: 46238.291 | N11: qxz5hes
A12: 155031332 | B12: MGU22 - SYSTEM INTEGRATION | C12: SINT | D12: SINT---MGU22_SWINT_04---PLATFORM_SW_BUILD/BITBAKE_TARGETS=mgu22 | E12: UNSTABLE | F12: https://asc.bmwgroup.net/bci/00780/job/SINT---MGU22_SWINT_04---PLATFORM_SW_BUILD/BITBAKE_TARGETS=mgu22/1595 | G12: https://asc.bmwgroup.net/bci/00780/job/SINT---MGU22_SWINT_04/1750 | H12: 46237.621 | I12: REGULAR_BUILD_FAILURE | J12: BUILD_BITBAKE_FAILURE | K12: Automatically classified by BCI | M12: 46237.733 | N12: SYSTEM
A13: 155031367 | B13: MGU22 - SYSTEM INTEGRATION | C13: SINT | D13: SINT---MGU22_SWINT_01---PLATFORM_SW_BUILD/BITBAKE_TARGETS=mgu22 | E13: UNSTABLE | F13: https://asc.bmwgroup.net/bci/00780/job/SINT---MGU22_SWINT_01---PLATFORM_SW_BUILD/BITBAKE_TARGETS=mgu22/3717 | G13: https://asc.bmwgroup.net/bci/00780/job/SINT---MGU22_SWINT_01/4192 | H13: 46237.621 | I13: REGULAR_BUILD_FAILURE | J13: BUILD_BITBAKE_FAILURE | K13: Automatically classified by BCI | M13: 46237.712 | N13: SYSTEM
A14: 155049102 | B14: MGU22 - SYSTEM INTEGRATION | C14: SINT | D14: SINT---MGU22_DEVCI_01---PLATFORM_SYSTEM_TESTS_HARDWARE_B1_HIGHF_22 | E14: UNSTABLE | F14: https://asc.bmwgroup.net/bci/03480/job/SINT---MGU22_DEVCI_01---PLATFORM_SYSTEM_TESTS_HARDWARE_B1_HIGHF_22/5300 | G14: https://asc.bmwgroup.net/bci/03480/job/SINT---MGU22_DEVCI_01/9270 | H14: 46238.224 | M14: 46238.331 | N14: SYSTEM
A15: 155058873 | B15: MGU22 - SYSTEM INTEGRATION | C15: SINT | D15: SINT---MGU22_DEVCI01_01_TBS---PLATFORM_SYSTEM_TESTS_VIRTUAL_MGU22 | E15: UNSTABLE | F15: https://asc.bmwgroup.net/bci/07080/job/SINT---MGU22_DEVCI01_01_TBS---PLATFORM_SYSTEM_TESTS_VIRTUAL_MGU22/972 | G15: https://asc.bmwgroup.net/bci/07080/job/SINT---MGU22_DEVCI01_01_TBS/1191 | H15: 46238.595 | I15: IRREGULAR_TEST_FAILURE | J15: TEST_OTHER_IRREGULAR_FAILURE | K15: MGU22: Test-execution-environment.posttests_can_asc_sanity_tests case failing | L15: SIT-53324 | M15: 46239.302 | N15: qxz5hes
A16: 155070050 | B16: MGU22 - SYSTEM INTEGRATION | C16: SINT | D16: SINT---MGU22_DEVCI01_01_TBS---PLATFORM_SYSTEM_TESTS_HARDWARE_B1_HIGHF_22_5 | E16: UNSTABLE | F16: https://asc.bmwgroup.net/bci/07080/job/SINT---MGU22_DEVCI01_01_TBS---PLATFORM_SYSTEM_TESTS_HARDWARE_B1_HIGHF_22_5/916 | G16: https://asc.bmwgroup.net/bci/07080/job/SINT---MGU22_DEVCI01_01_TBS/1191 | H16: 46239.143 | I16: IRREGULAR_TEST_FAILURE | J16: TEST_OTHER_IRREGULAR_FAILURE | K16: Setup/Worker issue | M16: 46239.324 | N16: qxz5hes
A17: 155069224 | B17: MGU22 - SYSTEM INTEGRATION | C17: SINT | D17: SINT---MGU22_DEVCI01_01_TBS---PLATFORM_SYSTEM_TESTS_HARDWARE_B1_HIGHF_22_4 | E17: UNSTABLE | F17: https://asc.bmwgroup.net/bci/07080/job/SINT---MGU22_DEVCI01_01_TBS---PLATFORM_SYSTEM_TESTS_HARDWARE_B1_HIGHF_22_4/945 | G17: https://asc.bmwgroup.net/bci/07080/job/SINT---MGU22_DEVCI01_01_TBS/1191 | H17: 46239.033 | M17: 46239.143 | N17: SYSTEM
A18: 155058874 | B18: MGU22 - SYSTEM INTEGRATION | C18: SINT | D18: SINT---MGU22_DEVCI01_01_TBS---PLATFORM_SYSTEM_TESTS_HARDWARE_B1_HIGHF_22 | E18: UNSTABLE | F18: https://asc.bmwgroup.net/bci/07080/job/SINT---MGU22_DEVCI01_01_TBS---PLATFORM_SYSTEM_TESTS_HARDWARE_B1_HIGHF_22/1012 | G18: https://asc.bmwgroup.net/bci/07080/job/SINT---MGU22_DEVCI01_01_TBS/1191 | H18: 46238.595 | M18: 46238.702 | N18: SYSTEM
A19: 155070592 | B19: MGU22 - SYSTEM INTEGRATION | C19: SINT | D19: SINT---MGU22_DEVCI_01---PLATFORM_SYSTEM_TESTS_HARDWARE_B1_HIGHF_22 | E19: UNSTABLE | F19: https://asc.bmwgroup.net/bci/03480/job/SINT---MGU22_DEVCI_01---PLATFORM_SYSTEM_TESTS_HARDWARE_B1_HIGHF_22/5302 | G19: https://asc.bmwgroup.net/bci/03480/job/SINT---MGU22_DEVCI_01/9272 | H19: 46239.225 | I19: IRREGULAR_TEST_FAILURE | J19: TEST_OTHER_IRREGULAR_FAILURE | K19: Setup/Worker issue | M19: 46239.324 | N19: qxz5hes
A20: 155093526 | B20: MGU22 - SYSTEM INTEGRATION | C20: SINT | D20: SINT---MGU22_DEVCI_01---PLATFORM_SYSTEM_TESTS_HARDWARE_B1_HIGHF_22 | E20: UNSTABLE | F20: https://asc.bmwgroup.net/bci/03480/job/SINT---MGU22_DEVCI_01---PLATFORM_SYSTEM_TESTS_HARDWARE_B1_HIGHF_22/5303 | G20: https://asc.bmwgroup.net/bci/03480/job/SINT---MGU22_DEVCI_01/9273 | H20: 46239.825 | I20: IRREGULAR_TEST_FAILURE | J20: TEST_OTHER_IRREGULAR_FAILURE | K20: Setup/Worker issue | M20: 46240.271 | N20: qxz5hes
A21: 155090612 | B21: MGU22 - SYSTEM INTEGRATION | C21: SINT | D21: SINT---MGU22_SWINT_04---PLATFORM_SW_BUILD/BITBAKE_TARGETS=mgu22 | E21: ABORTED | F21: https://asc.bmwgroup.net/bci/00780/job/SINT---MGU22_SWINT_04---PLATFORM_SW_BUILD/BITBAKE_TARGETS=mgu22/1596 | G21: https://asc.bmwgroup.net/bci/00780/job/SINT---MGU22_SWINT_04/1751 | H21: 46239.717 | I21: REGULAR_BUILD_FAILURE | J21: BUILD_USER_ABORT_FAILURE | K21: Automatically classified by BCI | M21: 46239.763 | N21: SYSTEM
A22: 155090617 | B22: MGU22 - SYSTEM INTEGRATION | C22: SINT | D22: SINT---MGU22_SWINT_01---PLATFORM_SW_BUILD/BITBAKE_TARGETS=mgu22 | E22: ABORTED | F22: https://asc.bmwgroup.net/bci/00780/job/SINT---MGU22_SWINT_01---PLATFORM_SW_BUILD/BITBAKE_TARGETS=mgu22/3718 | G22: https://asc.bmwgroup.net/bci/00780/job/SINT---MGU22_SWINT_01/4193 | H22: 46239.717 | I22: REGULAR_BUILD_FAILURE | J22: BUILD_USER_ABORT_FAILURE | K22: Automatically classified by BCI | M22: 46239.763 | N22: SYSTEM
A23: 155097750 | B23: MGU22 - SYSTEM INTEGRATION | C23: SINT | D23: SINT---MGU22_SWINT_01---PLATFORM_SYSTEM_TESTS_HARDWARE_B1_HIGHF_22 | E23: ABORTED | F23: https://asc.bmwgroup.net/bci/00780/job/SINT---MGU22_SWINT_01---PLATFORM_SYSTEM_TESTS_HARDWARE_B1_HIGHF_22/2623 | G23: https://asc.bmwgroup.net/bci/00780/job/SINT---MGU22_SWINT_01/4194 | H23: 46240.064 | I23: REGULAR_BUILD_FAILURE | J23: BUILD_USER_ABORT_FAILURE | K23: Automatically classified by BCI | M23: 46240.231 | N23: SYSTEM
A24: 155097955 | B24: MGU22 - SYSTEM INTEGRATION | C24: SINT | D24: SINT---MGU22_SWINT_04---PLATFORM_SYSTEM_TESTS_HARDWARE_B1_HIGHF_22 | E24: UNSTABLE | F24: https://asc.bmwgroup.net/bci/00780/job/SINT---MGU22_SWINT_04---PLATFORM_SYSTEM_TESTS_HARDWARE_B1_HIGHF_22/960 | G24: https://asc.bmwgroup.net/bci/00780/job/SINT---MGU22_SWINT_04/1752 | H24: 46240.112 | I24: IRREGULAR_TEST_FAILURE | J24: TEST_OTHER_IRREGULAR_FAILURE | K24: MGU22: Test-execution-environment.posttests_can_asc_sanity_tests case failing | L24: SIT-53324 | M24: 46240.271 | N24: qxz5hes
A25: 155108634 | B25: MGU22 - OSIS EU | C25: SINT | D25: SINT---MGU22_OSISEU_01---PLATFORM_SYSTEM_TESTS_HARDWARE_B1_HIGHF_22 | E25: UNSTABLE | F25: https://asc.bmwgroup.net/bci/01480/job/SINT---MGU22_OSISEU_01---PLATFORM_SYSTEM_TESTS_HARDWARE_B1_HIGHF_22/2553 | G25: https://asc.bmwgroup.net/bci/01480/job/SINT---MGU22_OSISEU_01/3587 | H25: 46240.678 | M25: 46240.79 | N25: SYSTEM
A26: 155107551 | B26: MGU22 - SYSTEM INTEGRATION | C26: SINT | D26: SINT---MGU22_DEVCI_02---PLATFORM_SYSTEM_TESTS_HARDWARE_B1_HIGHF_22 | E26: UNSTABLE | F26: https://asc.bmwgroup.net/bci/03480/job/SINT---MGU22_DEVCI_02---PLATFORM_SYSTEM_TESTS_HARDWARE_B1_HIGHF_22/3801 | G26: https://asc.bmwgroup.net/bci/03480/job/SINT---MGU22_DEVCI_02/6349 | H26: 46240.627 | I26: IRREGULAR_TEST_FAILURE | J26: TEST_OTHER_IRREGULAR_FAILURE | K26: MGU22: Test-execution-environment.posttests_can_asc_sanity_tests case failing | L26: SIT-53324 | M26: 46241.32 | N26: qxz5hes
A27: 155111068 | B27: MGU22 - SYSTEM INTEGRATION | C27: SINT | D27: SINT---MGU22_DEVCI01_01_TBS---PLATFORM_SYSTEM_TESTS_HARDWARE_B1_HIGHF_22_2 | E27: UNSTABLE | F27: https://asc.bmwgroup.net/bci/07080/job/SINT---MGU22_DEVCI01_01_TBS---PLATFORM_SYSTEM_TESTS_HARDWARE_B1_HIGHF_22_2/972 | G27: https://asc.bmwgroup.net/bci/07080/job/SINT---MGU22_DEVCI01_01_TBS/1192 | H27: 46240.807 | I27: IRREGULAR_TEST_FAILURE | J27: TEST_OTHER_IRREGULAR_FAILURE | K27: Setup/Worker issue | M27: 46241.319 | N27: qxz5hes
A28: 155107595 | B28: MGU22 - SYSTEM INTEGRATION | C28: SINT | D28: SINT---MGU22_DEVCI01_01_TBS---PLATFORM_SYSTEM_TESTS_HARDWARE_B1_HIGHF_22 | E28: UNSTABLE | F28: https://asc.bmwgroup.net/bci/07080/job/SINT---MGU22_DEVCI01_01_TBS---PLATFORM_SYSTEM_TESTS_HARDWARE_B1_HIGHF_22/1013 | G28: https://asc.bmwgroup.net/bci/07080/job/SINT---MGU22_DEVCI01_01_TBS/1192 | H28: 46240.631 | I28: IRREGULAR_TEST_FAILURE | J28: TEST_OTHER_IRREGULAR_FAILURE | K28: MGU22: Test-execution-environment.posttests_can_asc_sanity_tests case failing | L28: SIT-53324 | M28: 46241.32 | N28: qxz5hes
A29: 155113948 | B29: MGU22 - SYSTEM INTEGRATION | C29: SINT | D29: SINT---MGU22_DEVCI_01---PLATFORM_SYSTEM_TESTS_HARDWARE_B1_HIGHF_22 | E29: UNSTABLE | F29: https://asc.bmwgroup.net/bci/03480/job/SINT---MGU22_DEVCI_01---PLATFORM_SYSTEM_TESTS_HARDWARE_B1_HIGHF_22/5305 | G29: https://asc.bmwgroup.net/bci/03480/job/SINT---MGU22_DEVCI_01/9275 | H29: 46241.227 | I29: IRREGULAR_TEST_FAILURE | J29: TEST_OTHER_IRREGULAR_FAILURE | K29: MGU22: Test-execution-environment.posttests_can_asc_sanity_tests case failing | L29: SIT-53324 | M29: 46241.469 | N29: qxz5hes
A30: 155114212 | B30: MGU22 - SYSTEM INTEGRATION | C30: SINT | D30: SINT---MGU22_SWINT_04---PLATFORM_SYSTEM_TESTS_HARDWARE_B1_HIGHF_22 | E30: UNSTABLE | F30: https://asc.bmwgroup.net/bci/00780/job/SINT---MGU22_SWINT_04---PLATFORM_SYSTEM_TESTS_HARDWARE_B1_HIGHF_22/962 | G30: https://asc.bmwgroup.net/bci/00780/job/SINT---MGU22_SWINT_04/1754 | H30: 46241.293 | I30: IRREGULAR_TEST_FAILURE | J30: TEST_OTHER_IRREGULAR_FAILURE | K30: MGU22: Test-execution-environment.posttests_can_asc_sanity_tests case failing | L30: SIT-53324 | M30: 46241.469 | N30: qxz5hes
A31: 155129972 | B31: MGU22 - SYSTEM INTEGRATION | C31: SINT | D31: SINT---MGU22_SWINT_04---PLATFORM_SW_BUILD/BITBAKE_TARGETS=mgu22 | E31: ABORTED | F31: https://asc.bmwgroup.net/bci/00780/job/SINT---MGU22_SWINT_04---PLATFORM_SW_BUILD/BITBAKE_TARGETS=mgu22/1600 | G31: https://asc.bmwgroup.net/bci/00780/job/SINT---MGU22_SWINT_04/1755 | H31: 46241.447 | I31: REGULAR_BUILD_FAILURE | J31: BUILD_USER_ABORT_FAILURE | K31: Automatically classified by BCI | M31: 46241.448 | N31: SYSTEM
A32: 155130224 | B32: MGU22 - SYSTEM INTEGRATION | C32: SINT | D32: SINT---MGU22_SWINT_04---PLATFORM_SW_BUILD/BITBAKE_TARGETS=mgu22 | E32: UNSTABLE | F32: https://asc.bmwgroup.net/bci/00780/job/SINT---MGU22_SWINT_04---PLATFORM_SW_BUILD/BITBAKE_TARGETS=mgu22/1601 | G32: https://asc.bmwgroup.net/bci/00780/job/SINT---MGU22_SWINT_04/1756 | H32: 46241.452 | I32: REGULAR_BUILD_FAILURE | J32: BUILD_BITBAKE_FAILURE | M32: 46244.276 | N32: qxz5hes
A33: 155155018 | B33: MGU22 - OSIS EU | C33: SINT | D33: SINT---MGU22_OSISEU_01---PLATFORM_SW_BUILD/BITBAKE_TARGETS=mgu22 | E33: UNSTABLE | F33: https://asc.bmwgroup.net/bci/01480/job/SINT---MGU22_OSISEU_01---PLATFORM_SW_BUILD/BITBAKE_TARGETS=mgu22/3206 | G33: https://asc.bmwgroup.net/bci/01480/job/SINT---MGU22_OSISEU_01/3588 | H33: 46241.695 | I33: REGULAR_BUILD_FAILURE | J33: BUILD_BITBAKE_FAILURE | K33: Automatically classified by BCI | M33: 46241.711 | N33: SYSTEM

Sheet Statistics
A2: Total CI-Gate runs per organization MGU22% and baseline MGU22 per result (overall) | J2: Overall counts without any filtering
A3: DATE | B3: SUCCESS | C3: FAILED | D3: ABORTED | E3: ONGOING
A4: 46237 | B4: 0 | C4: 5 | D4: 1
A5: 46238 | B5: 6 | C5: 1 | D5: 0
A6: 46239 | B6: 4 | C6: 2 | D6: 4
A7: 46240 | B7: 4 | C7: 4 | D7: 0
A8: 46241 | B8: 6 | C8: 3 | D8: 1
A9: 46242 | B9: 4 | C9: 1 | D9: 0
A10: 46243 | B10: 4 | C10: 0 | D10: 0 | E10: 1
A12: Total Subcheck runs per organization MGU22% and baseline MGU22 per result (overall)
A13: DATE | B13: SUCCESS | C13: UNSTABLE | D13: FAILED | E13: ABORTED | F13: ONGOING
A14: 46237 | B14: 6 | C14: 8 | D14: 0 | E14: 2
A15: 46238 | B15: 31 | C15: 3 | D15: 0 | E15: 0
A16: 46239 | B16: 30 | C16: 4 | D16: 0 | E16: 5
A17: 46240 | B17: 42 | C17: 5 | D17: 0 | E17: 1
A18: 46241 | B18: 31 | C18: 7 | D18: 0 | E18: 2
A19: 46242 | B19: 24 | C19: 1 | D19: 0 | E19: 0
A20: 46243 | B20: 21 | C20: 0 | D20: 0 | E20: 0
A21: 46244 | B21: 2 | C21: 0 | D21: 0 | E21: 0 | F21: 1
A23: Total CI-Gate runs per organization MGU22% and baseline MGU22 per result (filtered) | J23: Potentially failure classified ci gates rules: - feature "ff_failure_classification" - plugin configuration "failure_classification_ignore_subchecks_regex" .*---domain|RSE_PIPELINE_BUILD|IDC_PIPELINE_BUILD|MGU22_PDX - feature "ff_failure_classification_ignore_for_additional_sts" - do not classify additional STs
A24: DATE | B24: SUCCESS | C24: FAILED | D24: ABORTED | E24: ONGOING
A25: 46237 | B25: 0 | C25: 5 | D25: 1 | E25: 0
A26: 46238 | B26: 2 | C26: 1 | D26: 0 | E26: 0
A27: 46239 | B27: 0 | C27: 2 | D27: 3 | E27: 0
A28: 46240 | B28: 4 | C28: 4 | D28: 0 | E28: 0
A29: 46241 | B29: 3 | C29: 2 | D29: 1 | E29: 0
A30: 46242 | B30: 1 | C30: 0 | D30: 0 | E30: 0
A31: 46243 | B31: 0 | C31: 0 | D31: 0 | E31: 1
A33: Total Subcheck runs per organization MGU22% and baseline MGU22 per result (filtered)
A34: DATE | B34: SUCCESS | C34: UNSTABLE | D34: FAILED | E34: ABORTED | F34: ONGOING
A35: 46237 | B35: 6 | C35: 7 | D35: 0 | E35: 2 | F35: 0
A36: 46238 | B36: 15 | C36: 3 | D36: 0 | E36: 0 | F36: 0
A37: 46239 | B37: 10 | C37: 4 | D37: 0 | E37: 4 | F37: 0
A38: 46240 | B38: 37 | C38: 5 | D38: 0 | E38: 1 | F38: 0
A39: 46241 | B39: 15 | C39: 6 | D39: 0 | E39: 2 | F39: 0
A40: 46242 | B40: 8 | C40: 0 | D40: 0 | E40: 0 | F40: 0
A41: 46243 | B41: 5 | C41: 0 | D41: 0 | E41: 0 | F41: 0
A42: 46244 | B42: 2 | C42: 0 | D42: 0 | E42: 0 | F42: 1
A44: Failure classified CI-Gate runs per organization MGU22% and baseline MGU22% per result (filtered) | J44: Classified ci gates rules: - potentailly failure classfied rules - feature ff_failure_classification_filter_platform_sw_build_pairs - filtering matrix run - matrix build - feature ff_failure_classification_suppress_retry - filtering retried builds
A45: DATE | B45: SUCCESS | C45: FAILED | D45: ABORTED
...

Sheet Report Diff
A1: Count of failure classified option executions not included in Report sheet (ignoring SUCCESS): 30
A2: EXECUTION_ID | B2: ORGANIZATION | C2: CI_STAGE | D2: JOB | E2: RESULT | F2: URL | G2: CI_GATE_URL | H2: TIMESTAMP
A3: 155030325 | B3: MGU22 - SYSTEM INTEGRATION | C3: SINT | D3: SINT---MGU22_SWINT_04 | E3: FAILED | F3: https://asc.bmwgroup.net/bci/00780/job/SINT---MGU22_SWINT_04/1749 | H3: 46237.465
A4: 155030327 | B4: MGU22 - SYSTEM INTEGRATION | C4: SINT | D4: SINT---MGU22_SWINT_01 | E4: ABORTED | F4: https://asc.bmwgroup.net/bci/00780/job/SINT---MGU22_SWINT_01/4191 | H4: 46237.465
A5: 155030344 | B5: MGU22 - SYSTEM INTEGRATION | C5: SINT | D5: SINT---MGU22_SWINT_04---PLATFORM_SW_BUILD | E5: UNSTABLE | F5: https://asc.bmwgroup.net/bci/00780/job/SINT---MGU22_SWINT_04---PLATFORM_SW_BUILD/1594 | G5: https://asc.bmwgroup.net/bci/00780/job/SINT---MGU22_SWINT_04/1749 | H5: 46237.466
A6: 155030348 | B6: MGU22 - SYSTEM INTEGRATION | C6: SINT | D6: SINT---MGU22_SWINT_01---PLATFORM_SW_BUILD | E6: ABORTED | F6: https://asc.bmwgroup.net/bci/00780/job/SINT---MGU22_SWINT_01---PLATFORM_SW_BUILD/3716 | G6: https://asc.bmwgroup.net/bci/00780/job/SINT---MGU22_SWINT_01/4191 | H6: 46237.466
A7: 155030940 | B7: MGU22 - BASE SYSTEM | C7: SINT | D7: SINT---MGU22_BSYS_02 | E7: FAILED | F7: https://asc.bmwgroup.net/bci/08480/job/SINT---MGU22_BSYS_02/1830 | H7: 46237.531
A8: 155031291 | B8: MGU22 - SYSTEM INTEGRATION | C8: SINT | D8: SINT---MGU22_SWINT_04 | E8: FAILED | F8: https://asc.bmwgroup.net/bci/00780/job/SINT---MGU22_SWINT_04/1750 | H8: 46237.62
A9: 155031300 | B9: MGU22 - SYSTEM INTEGRATION | C9: SINT | D9: SINT---MGU22_SWINT_01 | E9: FAILED | F9: https://asc.bmwgroup.net/bci/00780/job/SINT---MGU22_SWINT_01/4192 | H9: 46237.62
A10: 155031327 | B10: MGU22 - SYSTEM INTEGRATION | C10: SINT | D10: SINT---MGU22_SWINT_04---PLATFORM_SW_BUILD | E10: UNSTABLE | F10: https://asc.bmwgroup.net/bci/00780/job/SINT---MGU22_SWINT_04---PLATFORM_SW_BUILD/1595 | G10: https://asc.bmwgroup.net/bci/00780/job/SINT---MGU22_SWINT_04/1750 | H10: 46237.621
A11: 155031357 | B11: MGU22 - SYSTEM INTEGRATION | C11: SINT | D11: SINT---MGU22_SWINT_01---PLATFORM_SW_BUILD | E11: UNSTABLE | F11: https://asc.bmwgroup.net/bci/00780/job/SINT---MGU22_SWINT_01---PLATFORM_SW_BUILD/3717 | G11: https://asc.bmwgroup.net/bci/00780/job/SINT---MGU22_SWINT_01/4192 | H11: 46237.621
A12: 155043299 | B12: MGU22 - SYSTEM INTEGRATION | C12: SINT | D12: SINT---MGU22_DEVCI_01 | E12: FAILED | F12: https://asc.bmwgroup.net/bci/03480/job/SINT---MGU22_DEVCI_01/9270 | H12: 46237.919
A13: 155067831 | B13: MGU22 - SYSTEM INTEGRATION | C13: SINT | D13: SINT---MGU22_DEVCI_01 | E13: FAILED | F13: https://asc.bmwgroup.net/bci/03480/job/SINT---MGU22_DEVCI_01/9272 | H13: 46238.92
A14: 155077880 | B14: MGU22 - SYSTEM INTEGRATION | C14: SINT | D14: SINT---MGU22_DEVCI_01 | E14: FAILED | F14: https://asc.bmwgroup.net/bci/03480/job/SINT---MGU22_DEVCI_01/9273 | H14: 46239.522
A15: 155090589 | B15: MGU22 - SYSTEM INTEGRATION | C15: SINT | D15: SINT---MGU22_SWINT_04 | E15: ABORTED | F15: https://asc.bmwgroup.net/bci/00780/job/SINT---MGU22_SWINT_04/1751 | H15: 46239.716
A16: 155090595 | B16: MGU22 - SYSTEM INTEGRATION | C16: SINT | D16: SINT---MGU22_SWINT_01 | E16: ABORTED | F16: https://asc.bmwgroup.net/bci/00780/job/SINT---MGU22_SWINT_01/4193 | H16: 46239.716
A17: 155090610 | B17: MGU22 - SYSTEM INTEGRATION | C17: SINT | D17: SINT---MGU22_SWINT_04---PLATFORM_SW_BUILD | E17: ABORTED | F17: https://asc.bmwgroup.net/bci/00780/job/SINT---MGU22_SWINT_04---PLATFORM_SW_BUILD/1596 | G17: https://asc.bmwgroup.net/bci/00780/job/SINT---MGU22_SWINT_04/1751 | H17: 46239.717
A18: 155090616 | B18: MGU22 - SYSTEM INTEGRATION | C18: SINT | D18: SINT---MGU22_SWINT_01---PLATFORM_SW_BUILD | E18: ABORTED | F18: https://asc.bmwgroup.net/bci/00780/job/SINT---MGU22_SWINT_01---PLATFORM_SW_BUILD/3718 | G18: https://asc.bmwgroup.net/bci/00780/job/SINT---MGU22_SWINT_01/4193 | H18: 46239.717
A19: 155092435 | B19: MGU22 - SYSTEM INTEGRATION | C19: SINT | D19: SINT---MGU22_SWINT_01 | E19: ABORTED | F19: https://asc.bmwgroup.net/bci/00780/job/SINT---MGU22_SWINT_01/4194 | H19: 46239.763
A20: 155092438 | B20: MGU22 - SYSTEM INTEGRATION | C20: SINT | D20: SINT---MGU22_SWINT_04 | E20: FAILED | F20: https://asc.bmwgroup.net/bci/00780/job/SINT---MGU22_SWINT_04/1752 | H20: 46239.763
A21: 155100753 | B21: MGU22 - OSIS EU | C21: SINT | D21: SINT---MGU22_OSISEU_01 | E21: FAILED | F21: https://asc.bmwgroup.net/bci/01480/job/SINT---MGU22_OSISEU_01/3587 | H21: 46240.458
A22: 155105514 | B22: MGU22 - SYSTEM INTEGRATION | C22: SINT | D22: SINT---MGU22_DEVCI_02 | E22: FAILED | F22: https://asc.bmwgroup.net/bci/03480/job/SINT---MGU22_DEVCI_02/6349 | H22: 46240.555
A23: 155111895 | B23: MGU22 - SYSTEM INTEGRATION | C23: SINT | D23: SINT---MGU22_DEVCI_01 | E23: FAILED | F23: https://asc.bmwgroup.net/bci/03480/job/SINT---MGU22_DEVCI_01/9275 | H23: 46240.92
A24: 155112196 | B24: MGU22 - SYSTEM INTEGRATION | C24: SINT | D24: SINT---MGU22_SWINT_04 | E24: FAILED | F24: https://asc.bmwgroup.net/bci/00780/job/SINT---MGU22_SWINT_04/1754 | H24: 46240.944
A25: 155129916 | B25: MGU22 - SYSTEM INTEGRATION | C25: SINT | D25: SINT---MGU22_SWINT_04 | E25: ABORTED | F25: https://asc.bmwgroup.net/bci/00780/job/SINT---MGU22_SWINT_04/1755 | H25: 46241.446
A26: 155129966 | B26: MGU22 - SYSTEM INTEGRATION | C26: SINT | D26: SINT---MGU22_SWINT_04---PLATFORM_SW_BUILD | E26: ABORTED | F26: https://asc.bmwgroup.net/bci/00780/job/SINT---MGU22_SWINT_04---PLATFORM_SW_BUILD/1600 | G26: https://asc.bmwgroup.net/bci/00780/job/SINT---MGU22_SWINT_04/1755 | H26: 46241.447
A27: 155130118 | B27: MGU22 - SYSTEM INTEGRATION | C27: SINT | D27: SINT---MGU22_SWINT_04 | E27: FAILED | F27: https://asc.bmwgroup.net/bci/00780/job/SINT---MGU22_SWINT_04/1756 | H27: 46241.451
A28: 155130208 | B28: MGU22 - SYSTEM INTEGRATION | C28: SINT | D28: SINT---MGU22_SWINT_04---PLATFORM_SW_BUILD | E28: UNSTABLE | F28: https://asc.bmwgroup.net/bci/00780/job/SINT---MGU22_SWINT_04---PLATFORM_SW_BUILD/1601 | G28: https://asc.bmwgroup.net/bci/00780/job/SINT---MGU22_SWINT_04/1756 | H28: 46241.452
A29: 155154961 | B29: MGU22 - OSIS EU | C29: SINT | D29: SINT---MGU22_OSISEU_01 | E29: FAILED | F29: https://asc.bmwgroup.net/bci/01480/job/SINT---MGU22_OSISEU_01/3588 | H29: 46241.694
A30: 155155004 | B30: MGU22 - OSIS EU | C30: SINT | D30: SINT---MGU22_OSISEU_01---PLATFORM_SW_BUILD | E30: UNSTABLE | F30: https://asc.bmwgroup.net/bci/01480/job/SINT---MGU22_OSISEU_01---PLATFORM_SW_BUILD/3206 | G30: https://asc.bmwgroup.net/bci/01480/job/SINT---MGU22_OSISEU_01/3588 | H30: 46241.695
A31: 155168867 | B31: MGU22 - SYSTEM INTEGRATION | C31: SINT | D31: SINT---MGU22_DEVCI_01 | F31: https://asc.bmwgroup.net/bci/03480/job/SINT---MGU22_DEVCI_01/9279 | H31: 46243.919
A32: 155170735 | B32: MGU22 - SYSTEM INTEGRATION | C32: SINT | D32: SINT---MGU22_DEVCI_01---PLATFORM_SYSTEM_TESTS_HARDWARE_B1_HIGHF_22 | F32: https://asc.bmwgroup.net/bci/03480/job/SINT---MGU22_DEVCI_01---PLATFORM_SYSTEM_TESTS_HARDWARE_B1_HIGHF_22/5309 | G32: https://asc.bmwgroup.net/bci/03480/job/SINT---MGU22_DEVCI_01/9279 | H32: 46244.222
A33: Count of executions from Report sheet not included in failure classified option: 0

Sheet Calculations CI gates
B1: These values are for CI gates where failure did not occur on a subcheck
B3: CATEGORY | C3: SUBCATEGORY | D3: COUNT | E3: SUBCATEGORY % | F3: CATEGORY % | H3: Total (Failed + Aborted) | I3: =I4+I5 -> 0 | K3: Data source for chart "Failed CI gate runs" in sheet "Results CI gates"
B4: REGULAR_GIT_TREE_FAILURE | C4: GIT_MERGE_FAILURE | D4: 0 | E4: =D4/$D$40 -> #DIV/0! | F4: =SUM(E4:E6) -> #DIV/0! | H4: Aborted | I4: =D16 -> 0 | J4: =I4/I3 -> #DIV/0! | K4: =IF(L4<>" ",H15," ") | L4: =IF(I15>0,I15," ")
B5: REGULAR_GIT_TREE_FAILURE | C5: GIT_WRONG_TOPIC_FAILURE | D5: 0 | E5: =D5/$D$40 -> #DIV/0! | F5: =SUM(E4:E6) -> #DIV/0! | H5: Failed | I5: =D40-D16 -> 0 | K5: =IF(L5<>" ",H16," ") | L5: =IF(I16>0,I16," ")
B6: REGULAR_GIT_TREE_FAILURE | C6: GIT_OTHER_REGULAR_FAILURE | D6: 0 | E6: =D6/$D$40 -> #DIV/0! | F6: =SUM(E4:E6) -> #DIV/0! | H6: Failed Regularly | I6: =SUM(D4:D6,D9:D15,D23:D24,D35) -> 0 | J6: =I6/I3 -> #DIV/0! | K6: =IF(L6<>" ",H17," ") | L6: =IF(I17>0,I17," ")
B7: IRREGULAR_GIT_TREE_FAILURE | C7: GIT_TOPIC_FETCH_FAILURE | D7: 0 | E7: =D7/$D$40 -> #DIV/0! | F7: =SUM(E7:E8) -> #DIV/0! | H7: Failed Irregularly - SW baseline | I7: =SUM(D36) -> 0 | J7: =I7/I3 -> #DIV/0! | K7: =IF(L7<>" ",H18," ") | L7: =IF(I18>0,I18," ")
B8: IRREGULAR_GIT_TREE_FAILURE | C8: GIT_OTHER_IRREGULAR_FAILURE | D8: 0 | E8: =D8/$D$40 -> #DIV/0! | F8: =SUM(E7:E8) -> #DIV/0! | H8: Failed Irregularly - Toolchain | I8: =SUM(D7:D8,D17:D22,D25,D26:D28,D29:D34,D37,D38) -> 0 | J8: =I8/I3 -> #DIV/0! | K8: =IF(L8<>" ",H19," ") | L8: =IF(I19>0,I19," ")
B9: REGULAR_BUILD_FAILURE | C9: BUILD_BITBAKE_FAILURE | D9: 0 | E9: =D9/$D$40 -> #DIV/0! | F9: =SUM(E9:E15) -> #DIV/0! | K9: =IF(L9<>" ",H20," ") | L9: =IF(I20>0,I20," ")
B10: REGULAR_BUILD_FAILURE | C10: BUILD_QA_CHECK_FAILURE | D10: 0 | E10: =D10/$D$40 -> #DIV/0! | F10: =SUM(E9:E15) -> #DIV/0! | K10: =IF(L10<>" ",H21," ") | L10: =IF(I21>0,I21," ")
B11: REGULAR_BUILD_FAILURE | C11: BUILD_OTHER_REGULAR_FAILURE | D11: 0 | E11: =D11/$D$40 -> #DIV/0! | F11: =SUM(E9:E15) -> #DIV/0! | K11: =IF(L11<>" ",H22," ") | L11: =IF(I22>0,I22," ")
B12: REGULAR_BUILD_FAILURE | C12: BUILD_POSTPROCESSING_FAILURE | D12: 0 | E12: =D12/$D$40 -> #DIV/0! | F12: =SUM(E9:E15) -> #DIV/0! | K12: =IF(L12<>" ",H23," ") | L12: =IF(I23>0,I23," ")
B13: REGULAR_BUILD_FAILURE | C13: BUILD_SIGNED_COMPONENT_FAILURE | D13: 0 | E13: =D13/$D$40 -> #DIV/0! | F13: =SUM(E9:E15) -> #DIV/0! | K13: =IF(L13<>" ",H24," ") | L13: =IF(I24>0,I24," ")
B14: REGULAR_BUILD_FAILURE | C14: BUILD_SCRIPT_REGULAR_FAILURE | D14: 0 | E14: =D14/$D$40 -> #DIV/0! | F14: =SUM(E9:E15) -> #DIV/0! | H14: Row Labels | I14: Sum | K14: =IF(L14<>" ",H25," ") | L14: =IF(I25>0,I25," ")
B15: REGULAR_BUILD_FAILURE | C15: BUILD_SDK_UNIT_TEST_FAILURE | D15: 0 | E15: =D15/$D$40 -> #DIV/0! | F15: =SUM(E9:E15) -> #DIV/0! | H15: BUILD_BITBAKE_FAILURE | I15: 0 | K15: =IF(L15<>" ",H26," ") | L15: =IF(I26>0,I26," ")
B16: REGULAR_BUILD_FAILURE | C16: BUILD_USER_ABORT_FAILURE | D16: 0 | E16: =D16/$D$40 -> #DIV/0! | F16: =SUM(E9:E15) -> #DIV/0! | H16: BUILD_BITBAKE_TIMEOUT_FAILURE | I16: 0 | K16: =IF(L16<>" ",H27," ") | L16: =IF(I27>0,I27," ")
B17: IRREGULAR_BUILD_FAILURE | C17: BUILD_DEPENDENCY_FAILURE | D17: 0 | E17: =D17/$D$40 -> #DIV/0! | F17: =SUM(E17:E22) -> #DIV/0! | H17: BUILD_DEPENDENCY_FAILURE | I17: 0 | K17: =IF(L17<>" ",H28," ") | L17: =IF(I28>0,I28," ")
B18: IRREGULAR_BUILD_FAILURE | C18: BUILD_SCRIPT_FAILURE | D18: 0 | E18: =D18/$D$40 -> #DIV/0! | F18: =SUM(E17:E22) -> #DIV/0! | H18: BUILD_FETCH_URL_FAILURE | I18: 0 | K18: =IF(L18<>" ",H29," ") | L18: =IF(I29>0,I29," ")
B19: IRREGULAR_BUILD_FAILURE | C19: BUILD_FETCH_URL_FAILURE | D19: 0 | E19: =D19/$D$40 -> #DIV/0! | F19: =SUM(E17:E22) -> #DIV/0! | H19: BUILD_OTHER_IRREGULAR_FAILURE | I19: 0 | K19: =IF(L19<>" ",H30," ") | L19: =IF(I30>0,I30," ")
B20: IRREGULAR_BUILD_FAILURE | C20: BUILD_BITBAKE_TIMEOUT_FAILURE | D20: 0 | E20: =D20/$D$40 -> #DIV/0! | F20: =SUM(E17:E22) -> #DIV/0! | H20: BUILD_OTHER_REGULAR_FAILURE | I20: 0 | K20: =IF(L20<>" ",H31," ") | L20: =IF(I31>0,I31," ")
B21: IRREGULAR_BUILD_FAILURE | C21: BUILD_OUT_OF_RAM_FAILURE | D21: 0 | E21: =D21/$D$40 -> #DIV/0! | F21: =SUM(E17:E22) -> #DIV/0! | H21: BUILD_OUT_OF_RAM_FAILURE | I21: 0 | K21: =IF(L21<>" ",H32," ") -> FAILED_SUBCHECKS | L21: =IF(I32>0,I32," ") -> 20
B22: IRREGULAR_BUILD_FAILURE | C22: BUILD_OTHER_IRREGULAR_FAILURE | D22: 0 | E22: =D22/$D$40 -> #DIV/0! | F22: =SUM(E17:E22) -> #DIV/0! | H22: BUILD_POSTPROCESSING_FAILURE | I22: 0 | K22: =IF(L22<>" ",H33," ") | L22: =IF(I33>0,I33," ")
B23: REGULAR_ECU_FAILURE | C23: ECU_IR_OVERWRITTEN_FAILURE | D23: 0 | E23: =D23/$D$40 -> #DIV/0! | F23: =SUM(E23:E24) -> #DIV/0! | H23: BUILD_QA_CHECK_FAILURE | I23: 0 | K23: =IF(L23<>" ",H34," ") | L23: =IF(I34>0,I34," ")
B24: REGULAR_ECU_FAILURE | C24: ECU_OTHER_REGULAR_FAILURE | D24: 0 | E24: =D24/$D$40 -> #DIV/0! | F24: =SUM(E23:E24) -> #DIV/0! | H24: BUILD_SCRIPT_FAILURE | I24: 0 | K24: =IF(L24<>" ",H35," ") | L24: =IF(I35>0,I35," ")
B25: IRREGULAR_ECU_FAILURE | C25: ECU_OTHER_IRREGULAR_FAILURE | D25: 0 | E25: =D25/$D$40 -> #DIV/0! | F25: =SUM(E25) -> #DIV/0! | H25: BUILD_SCRIPT_REGULAR_FAILURE | I25: 0 | K25: =IF(L25<>" ",H36," ") | L25: =IF(I36>0,I36," ")
B26: IRREGULAR_TOOLCHAIN_FAILURE | C26: TOOLCHAIN_FILE_HANDLING_FAILURE | D26: 0 | E26: =D26/$D$40 -> #DIV/0! | F26: =SUM(E26:E28) -> #DIV/0! | H26: BUILD_SDK_UNIT_TEST_FAILURE | I26: 0 | K26: =IF(L26<>" ",H37," ") | L26: =IF(I37>0,I37," ")
B27: IRREGULAR_TOOLCHAIN_FAILURE | C27: TOOLCHAIN_CONFIG_FAILURE | D27: 0 | E27: =D27/$D$40 -> #DIV/0! | F27: =SUM(E26:E28) -> #DIV/0! | H27: BUILD_SIGNED_COMPONENT_FAILURE | I27: 0 | K27: =IF(L27<>" ",H38," ") | L27: =IF(I38>0,I38," ")
B28: IRREGULAR_TOOLCHAIN_FAILURE | C28: TOOLCHAIN_OTHER_FAILURE | D28: 0 | E28: =D28/$D$40 -> #DIV/0! | F28: =SUM(E26:E28) -> #DIV/0! | H28: BUILD_USER_ABORT_FAILURE | I28: 0 | K28: =IF(L28<>" ",H39," ") | L28: =IF(I39>0,I39," ")
B29: IRREGULAR_INFRASTRUCTURE_FAILURE | C29: INFRASTRUCTURE_NETWORK_FAILURE | D29: 0 | E29: =D29/$D$40 -> #DIV/0! | F29: =SUM(E29:E34) -> #DIV/0! | H29: ECU_IR_OVERWRITTEN_FAILURE | I29: 0 | K29: =IF(L29<>" ",H40," ") | L29: =IF(I40>0,I40," ")
B30: IRREGULAR_INFRASTRUCTURE_FAILURE | C30: INFRASTRUCTURE_SERVICE_FAILURE | D30: 0 | E30: =D30/$D$40 -> #DIV/0! | F30: =SUM(E29:E34) -> #DIV/0! | H30: ECU_OTHER_IRREGULAR_FAILURE | I30: 0 | K30: =IF(L30<>" ",H41," ") | L30: =IF(I41>0,I41," ")
B31: IRREGULAR_INFRASTRUCTURE_FAILURE | C31: INFRASTRUCTURE_ASCENT_FAILURE | D31: 0 | E31: =D31/$D$40 -> #DIV/0! | F31: =SUM(E29:E34) -> #DIV/0! | H31: ECU_OTHER_REGULAR_FAILURE | I31: 0 | K31: =IF(L31<>" ",H42," ") | L31: =IF(I42>0,I42," ")
B32: IRREGULAR_INFRASTRUCTURE_FAILURE | C32: INFRASTRUCTURE_CODECRAFT_ARTIFACTORY_FAILURE | D32: 0 | E32: =D32/$D$40 -> #DIV/0! | F32: =SUM(E29:E34) -> #DIV/0! | H32: FAILED_SUBCHECKS | I32: 20 | K32: =IF(L32<>" ",H43," ") | L32: =IF(I43>0,I43," ")
B33: IRREGULAR_INFRASTRUCTURE_FAILURE | C33: INFRASTRUCTURE_CODECRAFT_GITHUB_FAILURE | D33: 0 | E33: =D33/$D$40 -> #DIV/0! | F33: =SUM(E29:E34) -> #DIV/0! | H33: GIT_MERGE_FAILURE | I33: 0 | K33: =IF(L33<>" ",H44," ") | L33: =IF(I44>0,I44," ")
B34: IRREGULAR_INFRASTRUCTURE_FAILURE | C34: INFRASTRUCTURE_OTHER_FAILURE | D34: 0 | E34: =D34/$D$40 -> #DIV/0! | F34: =SUM(E29:E34) -> #DIV/0! | H34: GIT_OTHER_IRREGULAR_FAILURE | I34: 0 | K34: =IF(L34<>" ",H45," ") | L34: =IF(I45>0,I45," ")
B35: REGULAR_TEST_FAILURE | C35: TEST_CHANGE_RELATED | D35: 0 | E35: =D35/$D$40 -> #DIV/0! | F35: =SUM(E35) -> #DIV/0! | H35: GIT_OTHER_REGULAR_FAILURE | I35: 0 | K35: =IF(L35<>" ",H46," ") | L35: =IF(I46>0,I46," ")
B36: IRREGULAR_TEST_FAILURE | C36: TEST_GENERAL_ISSUE | D36: 0 | E36: =D36/$D$40 -> #DIV/0! | F36: =SUM(E36:E37) -> #DIV/0! | H36: GIT_TOPIC_FETCH_FAILURE | I36: 0 | K36: =IF(L36<>" ",H47," ") | L36: =IF(I47>0,I47," ")
B37: IRREGULAR_TEST_FAILURE | C37: TEST_OTHER_IRREGULAR_FAILURE | D37: 0 | E37: =D37/$D$40 -> #DIV/0! | F37: =SUM(E36:E37) -> #DIV/0! | H37: GIT_WRONG_TOPIC_FAILURE | I37: 0 | K37: =IF(L37<>" ",H48," ") | L37: =IF(I48>0,I48," ")
B38: UNCLASSIFIED_FAILURE | C38: UNCLASSIFIED_FAILURE | D38: 0 | E38: =D38/$D$40 -> #DIV/0! | F38: =SUM(E38) -> #DIV/0! | H38: INFRASTRUCTURE_ASCENT_FAILURE | I38: 0 | K38: =IF(L38<>" ",H49," ") | L38: =IF(I49>0,I49," ")
C39: FAILED_SUBCHECKS | D39: =SUM(IF(FREQUENCY(MATCH(B47:B67,B47:B67,0),MATCH(B47:B67,B47:B67,0))>0,1))-1 -> 20 | H39: INFRASTRUCTURE_CODECRAFT_ARTIFACTORY_FAILURE | I39: 0 | K39: =IF(L39<>" ",H50," ") | L39: =IF(I50>0,I50," ")
C40: Count Without Failed Subchecks | D40: =SUM(D4:D38) -> 0 | H40: INFRASTRUCTURE_CODECRAFT_GITHUB_FAILURE | I40: 0
H41: INFRASTRUCTURE_NETWORK_FAILURE | I41: 0
...

Sheet Result CI Gates
B3: Total number of CI gate runs for the week | C3: =SUM(Statistics!B4:D10) -> 50
B4: PASS | C4: =SUM(Statistics!B4:B10) -> 28
B5: ABORTED | C5: =SUM(Statistics!D4:D10) -> 6
B6: FAILED | C6: =SUM(Statistics!C4:C10) -> 16
B22: Failed CI Gate Runs
B23: ='Calculations CI gates'!K4 | C23: =SUM('Calculations CI gates'!L4) -> 0
B24: ='Calculations CI gates'!K5 | C24: =SUM('Calculations CI gates'!L5) -> 0
B25: ='Calculations CI gates'!K6 | C25: =SUM('Calculations CI gates'!L6) -> 0
B26: ='Calculations CI gates'!K7 | C26: =SUM('Calculations CI gates'!L7) -> 0
B27: ='Calculations CI gates'!K8 | C27: =SUM('Calculations CI gates'!L8) -> 0
B28: ='Calculations CI gates'!K9 | C28: =SUM('Calculations CI gates'!L9) -> 0
B29: ='Calculations CI gates'!K10 | C29: =SUM('Calculations CI gates'!L10) -> 0
B30: ='Calculations CI gates'!K11 | C30: =SUM('Calculations CI gates'!L11) -> 0
B31: ='Calculations CI gates'!K12 | C31: =SUM('Calculations CI gates'!L12) -> 0
B32: ='Calculations CI gates'!K13 | C32: =SUM('Calculations CI gates'!L13) -> 0
B33: ='Calculations CI gates'!K14 | C33: =SUM('Calculations CI gates'!L14) -> 0
B34: ='Calculations CI gates'!K15 | C34: =SUM('Calculations CI gates'!L15) -> 0
... B58: ='Calculations CI gates'!K39 | C58: =SUM('Calculations CI gates'!L39) -> 0

Sheet Calculations Subchecks
B1: These values are for failures on subchecks only, regardless of the CI gate where they belong
B3: CATEGORY | C3: SUBCATEGORY | D3: COUNT | E3: SUBCATEGORY % | F3: CATEGORY % | H3: Total (Failed + Aborted) | I3: =I4+I5 -> 21
B4: REGULAR_GIT_TREE_FAILURE | C4: GIT_MERGE_FAILURE | D4: 0 | E4: =D4/$D$39 -> 0 | F4: =SUM(E4:E6) -> 0 | H4: Aborted | I4: =D16 -> 5 | J4: =I4/I3 -> 0.23809524
B5: REGULAR_GIT_TREE_FAILURE | C5: GIT_WRONG_TOPIC_FAILURE | D5: 0 | E5: =D5/$D$39 -> 0 | F5: =SUM(E4:E6) -> 0 | H5: Failed | I5: =D39-D16 -> 16
B6: REGULAR_GIT_TREE_FAILURE | C6: GIT_OTHER_REGULAR_FAILURE | D6: 0 | E6: =D6/$D$39 -> 0 | F6: =SUM(E4:E6) -> 0 | H6: Failed Regularly | I6: =SUM(D4:D6,D9:D15,D23:D24,D35) -> 5 | J6: =I6/I3 -> 0.23809524
B7: IRREGULAR_GIT_TREE_FAILURE | C7: GIT_TOPIC_FETCH_FAILURE | D7: 0 | E7: =D7/$D$39 -> 0 | F7: =SUM(E7:E8) -> 0 | H7: Failed Irregularly - SW baseline | I7: =SUM(D36) -> 0 | J7: =I7/I3 -> 0
B8: IRREGULAR_GIT_TREE_FAILURE | C8: GIT_OTHER_IRREGULAR_FAILURE | D8: 0 | E8: =D8/$D$39 -> 0 | F8: =SUM(E7:E8) -> 0 | H8: Failed Irregularly - Toolchain | I8: =SUM(D7:D8,D17:D22,D25,D26:D28,D29:D34,D37,D38) -> 11 | J8: =I8/I3 -> 0.52380952
B9: REGULAR_BUILD_FAILURE | C9: BUILD_BITBAKE_FAILURE | D9: 5 | E9: =D9/$D$39 -> 0.23809524 | F9: =SUM(E9:E15) -> 0.23809524
B10: REGULAR_BUILD_FAILURE | C10: BUILD_QA_CHECK_FAILURE | D10: 0 | E10: =D10/$D$39 -> 0 | F10: =SUM(E9:E15) -> 0.23809524
B11: REGULAR_BUILD_FAILURE | C11: BUILD_OTHER_REGULAR_FAILURE | D11: 0 | E11: =D11/$D$39 -> 0 | F11: =SUM(E9:E15) -> 0.23809524
B12: REGULAR_BUILD_FAILURE | C12: BUILD_POSTPROCESSING_FAILURE | D12: 0 | E12: =D12/$D$39 -> 0 | F12: =SUM(E9:E15) -> 0.23809524
B13: REGULAR_BUILD_FAILURE | C13: BUILD_SIGNED_COMPONENT_FAILURE | D13: 0 | E13: =D13/$D$39 -> 0 | F13: =SUM(E9:E15) -> 0.23809524
B14: REGULAR_BUILD_FAILURE | C14: BUILD_SCRIPT_REGULAR_FAILURE | D14: 0 | E14: =D14/$D$39 -> 0 | F14: =SUM(E9:E15) -> 0.23809524
B15: REGULAR_BUILD_FAILURE | C15: BUILD_SDK_UNIT_TEST_FAILURE | D15: 0 | E15: =D15/$D$39 -> 0 | F15: =SUM(E9:E15) -> 0.23809524
B16: REGULAR_BUILD_FAILURE | C16: BUILD_USER_ABORT_FAILURE | D16: 5 | E16: =D16/$D$39 -> 0.23809524 | F16: =SUM(E9:E15) -> 0.23809524
B17: IRREGULAR_BUILD_FAILURE | C17: BUILD_DEPENDENCY_FAILURE | D17: 0 | E17: =D17/$D$39 -> 0 | F17: =SUM(E17:E22) -> 0
B18: IRREGULAR_BUILD_FAILURE | C18: BUILD_SCRIPT_FAILURE | D18: 0 | E18: =D18/$D$39 -> 0 | F18: =SUM(E17:E22) -> 0
B19: IRREGULAR_BUILD_FAILURE | C19: BUILD_FETCH_URL_FAILURE | D19: 0 | E19: =D19/$D$39 -> 0 | F19: =SUM(E17:E22) -> 0
B20: IRREGULAR_BUILD_FAILURE | C20: BUILD_BITBAKE_TIMEOUT_FAILURE | D20: 0 | E20: =D20/$D$39 -> 0 | F20: =SUM(E17:E22) -> 0
B21: IRREGULAR_BUILD_FAILURE | C21: BUILD_OUT_OF_RAM_FAILURE | D21: 0 | E21: =D21/$D$39 -> 0 | F21: =SUM(E17:E22) -> 0
B22: IRREGULAR_BUILD_FAILURE | C22: BUILD_OTHER_IRREGULAR_FAILURE | D22: 0 | E22: =D22/$D$39 -> 0 | F22: =SUM(E17:E22) -> 0
B23: REGULAR_ECU_FAILURE | C23: ECU_IR_OVERWRITTEN_FAILURE | D23: 0 | E23: =D23/$D$39 -> 0 | F23: =SUM(E23:E24) -> 0
B24: REGULAR_ECU_FAILURE | C24: ECU_OTHER_REGULAR_FAILURE | D24: 0 | E24: =D24/$D$39 -> 0 | F24: =SUM(E23:E24) -> 0
B25: IRREGULAR_ECU_FAILURE | C25: ECU_OTHER_IRREGULAR_FAILURE | D25: 0 | E25: =D25/$D$39 -> 0 | F25: =SUM(E25) -> 0
B26: IRREGULAR_TOOLCHAIN_FAILURE | C26: TOOLCHAIN_FILE_HANDLING_FAILURE | D26: 0 | E26: =D26/$D$39 -> 0 | F26: =SUM(E26:E28) -> 0
B27: IRREGULAR_TOOLCHAIN_FAILURE | C27: TOOLCHAIN_CONFIG_FAILURE | D27: 0 | E27: =D27/$D$39 -> 0 | F27: =SUM(E26:E28) -> 0
B28: IRREGULAR_TOOLCHAIN_FAILURE | C28: TOOLCHAIN_OTHER_FAILURE | D28: 0 | E28: =D28/$D$39 -> 0 | F28: =SUM(E26:E28) -> 0
B29: IRREGULAR_INFRASTRUCTURE_FAILURE | C29: INFRASTRUCTURE_NETWORK_FAILURE | D29: 0 | E29: =D29/$D$39 -> 0 | F29: =SUM(E29:E34) -> 0
B30: IRREGULAR_INFRASTRUCTURE_FAILURE | C30: INFRASTRUCTURE_SERVICE_FAILURE | D30: 0 | E30: =D30/$D$39 -> 0 | F30: =SUM(E29:E34) -> 0
B31: IRREGULAR_INFRASTRUCTURE_FAILURE | C31: INFRASTRUCTURE_ASCENT_FAILURE | D31: 0 | E31: =D31/$D$39 -> 0 | F31: =SUM(E29:E34) -> 0
B32: IRREGULAR_INFRASTRUCTURE_FAILURE | C32: INFRASTRUCTURE_CODECRAFT_ARTIFACTORY_FAILURE | D32: 0 | E32: =D32/$D$39 -> 0 | F32: =SUM(E29:E34) -> 0
B33: IRREGULAR_INFRASTRUCTURE_FAILURE | C33: INFRASTRUCTURE_CODECRAFT_GITHUB_FAILURE | D33: 0 | E33: =D33/$D$39 -> 0 | F33: =SUM(E29:E34) -> 0
B34: IRREGULAR_INFRASTRUCTURE_FAILURE | C34: INFRASTRUCTURE_OTHER_FAILURE | D34: 0 | E34: =D34/$D$39 -> 0 | F34: =SUM(E29:E34) -> 0
B35: REGULAR_TEST_FAILURE | C35: TEST_CHANGE_RELATED | D35: 0 | E35: =D35/$D$39 -> 0 | F35: =SUM(E35) -> 0
B36: IRREGULAR_TEST_FAILURE | C36: TEST_GENERAL_ISSUE | D36: 0 | E36: =D36/$D$39 -> 0 | F36: =SUM(E36:E37) -> 0.52380952
B37: IRREGULAR_TEST_FAILURE | C37: TEST_OTHER_IRREGULAR_FAILURE | D37: 11 | E37: =D37/$D$39 -> 0.52380952 | F37: =SUM(E36:E37) -> 0.52380952
B38: UNCLASSIFIED_FAILURE | C38: UNCLASSIFIED_FAILURE | D38: =SUM(COUNTIFS('Report Subchecks'!J:J,C38)) -> 0 | E38: =D38/$D$39 -> 0 | F38: =SUM(E38) -> 0
D39: =SUM(D4:D38) -> 21

Sheet Results Subchecks
E3: Irregular toolchain/services failures and SW baseline failure rate in subchecks = | F3: =""& FIXED(F24*100+F47*100,1)&"%" & " ( " & FIXED(F24*100,1)& "%" & " + " & FIXED(F47*100,1) &"%" & " )" -> #VALUE!
C6: Top Contributors | E6: Regular Failures | F6: ='Calculations Subchecks'!J6 -> 0.23809524
B7: BUILD_BITBAKE_FAILURE | C7: ='Calculations Subchecks'!E9 -> 0.23809524 | E7: =IF(F7<>" ",B7," ") -> BUILD_BITBAKE_FAILURE | F7: =IF(C7>0,C7," ") -> 0.23809524
B8: TEST_CHANGE_RELATED | C8: ='Calculations Subchecks'!E35 -> 0 | E8: =IF(F8<>" ",B8," ") | F8: =IF(C8>0,C8," ")
B9: BUILD_QA_CHECK_FAILURE | C9: ='Calculations Subchecks'!E10 -> 0 | E9: =IF(F9<>" ",B9," ") | F9: =IF(C9>0,C9," ")
B10: BUILD_POSTPROCESSING_FAILURE | C10: ='Calculations Subchecks'!E12 -> 0 | E10: =IF(F10<>" ",B10," ") | F10: =IF(C10>0,C10," ")
B11: GIT_MERGE_FAILURE | C11: ='Calculations Subchecks'!E12 -> 0 | E11: =IF(F11<>" ",B11," ") | F11: =IF(C11>0,C11," ")
B12: ECU_IR_OVERWRITTEN_FAILURE | C12: ='Calculations Subchecks'!E23 -> 0 | E12: =IF(F12<>" ",B12," ") | F12: =IF(C12>0,C12," ")
B13: ECU_OTHER_REGULAR_FAILURE | C13: ='Calculations Subchecks'!E24 -> 0 | E13: =IF(F13<>" ",B13," ") | F13: =IF(C13>0,C13," ")
B14: BUILD_SCRIPT_REGULAR_FAILURE | C14: ='Calculations Subchecks'!E14 -> 0 | E14: =IF(F14<>" ",B14," ") | F14: =IF(C14>0,C14," ")
B15: GIT_OTHER_REGULAR_FAILURE | C15: ='Calculations Subchecks'!E6 -> 0 | E15: =IF(F15<>" ",B15," ") | F15: =IF(C15>0,C15," ")
B16: GIT_WRONG_TOPIC_FAILURE | C16: ='Calculations Subchecks'!E5 -> 0 | E16: =IF(F16<>" ",B16," ") | F16: =IF(C16>0,C16," ")
B17: BUILD_OTHER_REGULAR_FAILURE | C17: ='Calculations Subchecks'!E11 -> 0 | E17: =IF(F17<>" ",B17," ") | F17: =IF(C17>0,C17," ")
B18: BUILD_SDK_UNIT_TEST_FAILURE | C18: ='Calculations Subchecks'!E15 -> 0 | E18: =IF(F18<>" ",B18," ") | F18: =IF(C18>0,C18," ")
B19: BUILD_SIGNED_COMPONENT_FAILURE | C19: ='Calculations Subchecks'!E13 -> 0 | E19: =IF(F19<>" ",B19," ") | F19: =IF(C19>0,C19," ")
B20: BUILD_USER_ABORT_FAILURE | C20: ='Calculations Subchecks'!E16 -> 0.23809524 | E20: =IF(F20<>" ",B20," ") -> BUILD_USER_ABORT_FAILURE | F20: =IF(C20>0,C20," ") -> 0.23809524
C24: Top Contributors | E24: Irregular toolchain/services/infrastructure Failures | F24: ='Calculations Subchecks'!J8 -> 0.52380952
B25: BUILD_OTHER_IRREGULAR_FAILURE | C25: ='Calculations Subchecks'!E22 -> 0 | E25: =IF(F25<>" ",B25," ") | F25: =IF(C25>0,C25," ")
B26: INFRASTRUCTURE_OTHER_FAILURE | C26: ='Calculations Subchecks'!E34 -> 0 | E26: =IF(F26<>" ",B26," ") | F26: =IF(C26>0,C26," ")
B27: TOOLCHAIN_OTHER_FAILURE | C27: ='Calculations Subchecks'!E28 -> 0 | E27: =IF(F27<>" ",B27," ") | F27: =IF(C27>0,C27," ")
